Workbook
Name SILVERBASE: #REF!
Name SILVERBASE: #REF!

Sheet Customs Invoice
A1: PT. VERONIQUE INDONESIA
A2: Jl. Raya Purwonegoro Rt. 007/003, Purwonegoro, Banjarnegara, Jawa Tengah, Zip Code : 53472, INDONESIA
A3: INVOICE
A4: Seller: | B4: PT. VERONIQUE INDONESIA | I4: Invoice No. & Date :
B5: Jl. Raya Purwonegoro Rt. 007/003 Purwonegoro Banjarnegara | I5: L/C No. & Date) :
B6: Jawa Tengah Zip Code : 53472 INDONESIA | I6: BILL TO : | M6: NEW MERCHANDISE
B7: NPWP : 0315202689-529000
B8: Tel : 62-286-598-8594 Fax : 62-286-598-8650
A9: Consignee:
I12: "GSP eligible Article"
I13: Other References: | K13: Country of Origin : | L13: INDONESIA
K14: B/L No. :
A15: Departure Date: | D15: COUNTRY OF ORIGIN: INDONESIA | K15: A/C No. :
A16: Vessel/Flight : | D16: From : INDONESIA | K16: C/T No. : | L16: 1
A17: To : | I17: Terms of Payment: | K17: 30 Day's Net
B19: BOX 1 = GOLD JEWELRY
B20: No | C20: ID Code | D20: USA harmonized code | E20: Item | F20: ID | G20: Qty/Pcs,Pair | I20: N.Weight | J20: G.Weight | K20: Unit Value (material & manufacturing cost) | L20: Total Value (material & manufacturing cost) | M20: Manufacturing Cost (nilai maklon) | N20: Dia Value | O20: Gold Value | P20: Manufacturing + Dia + Gold for US | R20: Total Value | S20: N.Weight
B21: 1 | C21: =CONCATENATE("MFGG-",MID(E21,1,3),MID(E21,10,1),"-IDD") -> #N/A | D21: =VLOOKUP(F21,Sheet2!$A$2:$D$31,4,0) -> #N/A | E21: =VLOOKUP(F21,Sheet2!$A$2:$D$31,2,0) -> #N/A | H21: =VLOOKUP(F21,Sheet2!$A$2:$D$31,3,0) -> #N/A | J21: =ROUND((I21/$I$164)*$J$164,2) -> #DIV/0! | K21: =L21/G21 -> #DIV/0! | R21: =L21 -> 0 | S21: =I21 -> 0
B22: 2 | C22: =CONCATENATE("MFGG-",MID(E22,1,3),MID(E22,10,1),"-IDD") -> #N/A | D22: =VLOOKUP(F22,Sheet2!$A$2:$D$31,4,0) -> #N/A | E22: =VLOOKUP(F22,Sheet2!$A$2:$D$31,2,0) -> #N/A | H22: =VLOOKUP(F22,Sheet2!$A$2:$D$31,3,0) -> #N/A | K22: =L22/G22 -> #DIV/0! | R22: =L22 -> 0 | S22: =I22 -> 0
B23: 3 | C23: =CONCATENATE("MFGG-",MID(E23,1,3),MID(E23,10,1),"-IDD") -> #N/A | D23: =VLOOKUP(F23,Sheet2!$A$2:$D$31,4,0) -> #N/A | E23: =VLOOKUP(F23,Sheet2!$A$2:$D$31,2,0) -> #N/A | H23: =VLOOKUP(F23,Sheet2!$A$2:$D$31,3,0) -> #N/A | K23: =L23/G23 -> #DIV/0! | R23: =L23 -> 0 | S23: =I23 -> 0
B24: 4 | C24: =CONCATENATE("MFGG-",MID(E24,1,3),MID(E24,10,1),"-IDD") -> #N/A | D24: =VLOOKUP(F24,Sheet2!$A$2:$D$31,4,0) -> #N/A | E24: =VLOOKUP(F24,Sheet2!$A$2:$D$31,2,0) -> #N/A | H24: =VLOOKUP(F24,Sheet2!$A$2:$D$31,3,0) -> #N/A | K24: =L24/G24 -> #DIV/0! | R24: =L24 -> 0 | S24: =I24 -> 0
B25: 5 | C25: =CONCATENATE("MFGG-",MID(E25,1,3),MID(E25,10,1),"-IDD") -> #N/A | D25: =VLOOKUP(F25,Sheet2!$A$2:$D$31,4,0) -> #N/A | E25: =VLOOKUP(F25,Sheet2!$A$2:$D$31,2,0) -> #N/A | H25: =VLOOKUP(F25,Sheet2!$A$2:$D$31,3,0) -> #N/A | K25: =L25/G25 -> #DIV/0! | R25: =L25 -> 0 | S25: =I25 -> 0
B26: 6 | C26: =CONCATENATE("MFGG-",MID(E26,1,3),MID(E26,10,1),"-IDD") -> #N/A | D26: =VLOOKUP(F26,Sheet2!$A$2:$D$31,4,0) -> #N/A | E26: =VLOOKUP(F26,Sheet2!$A$2:$D$31,2,0) -> #N/A | H26: =VLOOKUP(F26,Sheet2!$A$2:$D$31,3,0) -> #N/A | K26: =L26/G26 -> #DIV/0! | R26: =L26 -> 0 | S26: =I26 -> 0
B27: 7 | C27: =CONCATENATE("MFGG-",MID(E27,1,3),MID(E27,10,1),"-IDD") -> #N/A | D27: =VLOOKUP(F27,Sheet2!$A$2:$D$31,4,0) -> #N/A | E27: =VLOOKUP(F27,Sheet2!$A$2:$D$31,2,0) -> #N/A | H27: =VLOOKUP(F27,Sheet2!$A$2:$D$31,3,0) -> #N/A | K27: =L27/G27 -> #DIV/0! | R27: =L27 -> 0 | S27: =I27 -> 0
B28: 8 | C28: =CONCATENATE("MFGG-",MID(E28,1,3),MID(E28,10,1),"-IDD") -> #N/A | D28: =VLOOKUP(F28,Sheet2!$A$2:$D$31,4,0) -> #N/A | E28: =VLOOKUP(F28,Sheet2!$A$2:$D$31,2,0) -> #N/A | H28: =VLOOKUP(F28,Sheet2!$A$2:$D$31,3,0) -> #N/A | K28: =L28/G28 -> #DIV/0! | R28: =L28 -> 0 | S28: =I28 -> 0
B29: 9 | C29: =CONCATENATE("MFGG-",MID(E29,1,3),MID(E29,10,1),"-IDD") -> #N/A | D29: =VLOOKUP(F29,Sheet2!$A$2:$D$31,4,0) -> #N/A | E29: =VLOOKUP(F29,Sheet2!$A$2:$D$31,2,0) -> #N/A | H29: =VLOOKUP(F29,Sheet2!$A$2:$D$31,3,0) -> #N/A | K29: =L29/G29 -> #DIV/0! | R29: =L29 -> 0 | S29: =I29 -> 0
B30: 10 | C30: =CONCATENATE("MFGG-",MID(E30,1,3),MID(E30,10,1),"-IDD") -> #N/A | D30: =VLOOKUP(F30,Sheet2!$A$2:$D$31,4,0) -> #N/A | E30: =VLOOKUP(F30,Sheet2!$A$2:$D$31,2,0) -> #N/A | F30: - | H30: =VLOOKUP(F30,Sheet2!$A$2:$D$31,3,0) -> #N/A | K30: =L30/G30 -> #DIV/0! | R30: =L30 -> 0 | S30: =I30 -> 0
B31: 11 | C31: =CONCATENATE("MFGG-",MID(E31,1,3),MID(E31,10,1),"-IDD") -> #N/A | D31: =VLOOKUP(F31,Sheet2!$A$2:$D$31,4,0) -> #N/A | E31: =VLOOKUP(F31,Sheet2!$A$2:$D$31,2,0) -> #N/A | F31: - | H31: =VLOOKUP(F31,Sheet2!$A$2:$D$31,3,0) -> #N/A | K31: =L31/G31 -> #DIV/0! | R31: =L31 -> 0 | S31: =I31 -> 0
B32: 12 | C32: =CONCATENATE("MFGG-",MID(E32,1,3),MID(E32,10,1),"-IDD") -> #N/A | D32: =VLOOKUP(F32,Sheet2!$A$2:$D$31,4,0) -> #N/A | E32: =VLOOKUP(F32,Sheet2!$A$2:$D$31,2,0) -> #N/A | F32: - | H32: =VLOOKUP(F32,Sheet2!$A$2:$D$31,3,0) -> #N/A | K32: =L32/G32 -> #DIV/0! | R32: =L32 -> 0 | S32: =I32 -> 0
B33: 13 | C33: =CONCATENATE("MFGG-",MID(E33,1,3),MID(E33,10,1),"-IDD") -> #N/A | D33: =VLOOKUP(F33,Sheet2!$A$2:$D$31,4,0) -> #N/A | E33: =VLOOKUP(F33,Sheet2!$A$2:$D$31,2,0) -> #N/A | F33: - | H33: =VLOOKUP(F33,Sheet2!$A$2:$D$31,3,0) -> #N/A | K33: =L33/G33 -> #DIV/0! | R33: =L33 -> 0 | S33: =I33 -> 0
B34: 14 | C34: =CONCATENATE("MFGG-",MID(E34,1,3),MID(E34,10,1),"-IDD") -> #N/A | D34: =VLOOKUP(F34,Sheet2!$A$2:$D$31,4,0) -> #N/A | E34: =VLOOKUP(F34,Sheet2!$A$2:$D$31,2,0) -> #N/A | F34: - | H34: =VLOOKUP(F34,Sheet2!$A$2:$D$31,3,0) -> #N/A | K34: =L34/G34 -> #DIV/0! | R34: =L34 -> 0 | S34: =I34 -> 0
B35: 15 | C35: =CONCATENATE("MFGG-",MID(E35,1,3),MID(E35,10,1),"-IDD") -> #N/A | D35: =VLOOKUP(F35,Sheet2!$A$2:$D$31,4,0) -> #N/A | E35: =VLOOKUP(F35,Sheet2!$A$2:$D$31,2,0) -> #N/A | F35: - | H35: =VLOOKUP(F35,Sheet2!$A$2:$D$31,3,0) -> #N/A | K35: =L35/G35 -> #DIV/0! | R35: =L35 -> 0 | S35: =I35 -> 0
B36: 16 | C36: =CONCATENATE("MFGG-",MID(E36,1,3),MID(E36,10,1),"-IDD") -> #N/A | D36: =VLOOKUP(F36,Sheet2!$A$2:$D$31,4,0) -> #N/A | E36: =VLOOKUP(F36,Sheet2!$A$2:$D$31,2,0) -> #N/A | F36: - | H36: =VLOOKUP(F36,Sheet2!$A$2:$D$31,3,0) -> #N/A | K36: =L36/G36 -> #DIV/0! | R36: =L36 -> 0 | S36: =I36 -> 0
B37: 17 | C37: =CONCATENATE("MFGG-",MID(E37,1,3),MID(E37,10,1),"-IDD") -> #N/A | D37: =VLOOKUP(F37,Sheet2!$A$2:$D$31,4,0) -> #N/A | E37: =VLOOKUP(F37,Sheet2!$A$2:$D$31,2,0) -> #N/A | F37: - | H37: =VLOOKUP(F37,Sheet2!$A$2:$D$31,3,0) -> #N/A | K37: =L37/G37 -> #DIV/0! | R37: =L37 -> 0 | S37: =I37 -> 0
B38: 18 | C38: =CONCATENATE("MFGG-",MID(E38,1,3),MID(E38,10,1),"-IDD") -> #N/A | D38: =VLOOKUP(F38,Sheet2!$A$2:$D$31,4,0) -> #N/A | E38: =VLOOKUP(F38,Sheet2!$A$2:$D$31,2,0) -> #N/A | F38: - | H38: =VLOOKUP(F38,Sheet2!$A$2:$D$31,3,0) -> #N/A | K38: =L38/G38 -> #DIV/0! | R38: =L38 -> 0 | S38: =I38 -> 0
B39: 19 | C39: =CONCATENATE("MFGG-",MID(E39,1,3),MID(E39,10,1),"-IDD") -> #N/A | D39: =VLOOKUP(F39,Sheet2!$A$2:$D$31,4,0) -> #N/A | E39: =VLOOKUP(F39,Sheet2!$A$2:$D$31,2,0) -> #N/A | F39: - | H39: =VLOOKUP(F39,Sheet2!$A$2:$D$31,3,0) -> #N/A | K39: =L39/G39 -> #DIV/0! | R39: =L39 -> 0 | S39: =I39 -> 0
B40: 20 | C40: =CONCATENATE("MFGG-",MID(E40,1,3),MID(E40,10,1),"-IDD") -> #N/A | D40: =VLOOKUP(F40,Sheet2!$A$2:$D$31,4,0) -> #N/A | E40: =VLOOKUP(F40,Sheet2!$A$2:$D$31,2,0) -> #N/A | F40: - | H40: =VLOOKUP(F40,Sheet2!$A$2:$D$31,3,0) -> #N/A | K40: =L40/G40 -> #DIV/0! | R40: =L40 -> 0 | S40: =I40 -> 0
E41: TOTAL | G41: =SUM(G21:G40) -> 0 | I41: =SUM(I21:I40) -> 0 | J41: =SUM(J21:J40) -> #DIV/0! | L41: =SUM(L21:L40) -> 0 | M41: =SUM(M21:M40) -> 0 | N41: =SUM(N21:N40) -> 0 | O41: =SUM(O21:O40) -> 0 | P41: =SUM(P21:P40) -> 0
B43: BOX 2 = GOLD JEWELRY
B44: No | C44: ID Code | D44: USA harmonized code | E44: Item | F44: ID | G44: Qty/Pcs,Pair | I44: N.Weight | J44: G.Weight | K44: Unit Value (material & manufacturing cost) | L44: Total Value (material & manufacturing cost) | M44: Manufacturing Cost (nilai maklon) | P44: Manufacturing + Dia + Gold for US
...

Sheet PL
A1: PT. VERONIQUE INDONESIA
A2: Jl. Raya Purwonegoro Rt. 007/003, Purwonegoro, Banjarnegara, Jawa Tengah, Zip Code : 53472, INDONESIA
A3: PACKING LIST
A4: Seller: | B4: PT. VERONIQUE INDONESIA | I4: Invoice No. & Date : | K4: ='Customs Invoice'!K4 -> 0 | L4: ='Customs Invoice'!L4 -> 0
B5: Jl. Raya Purwonegoro Rt. 007/003 Purwonegoro Banjarnegara | I5: L/C No. & Date) :
B6: Jawa Tengah Zip Code : 53472 INDONESIA | I6: ='Customs Invoice'!I6 -> BILL TO : | K6: ='Customs Invoice'!K6 -> 0 | M6: NEW MERCHANDISE
B7: NPWP : 0315202689-529000 | K7: ='Customs Invoice'!K7 -> 0
B8: Tel : 62-286-598-8594 Fax : 62-286-598-8650 | K8: ='Customs Invoice'!K8 -> 0
A9: Consignee: | B9: ='Customs Invoice'!B9 -> 0 | K9: ='Customs Invoice'!K9 -> 0
B10: ='Customs Invoice'!B10 -> 0 | K10: ='Customs Invoice'!K10 -> 0
B11: ='Customs Invoice'!B11 -> 0 | K11: ='Customs Invoice'!K11 -> 0
B12: ='Customs Invoice'!B12 -> 0 | I12: "GSP eligible Article"
B13: ='Customs Invoice'!B13 -> 0 | I13: Other References: | K13: Country of Origin : | L13: INDONESIA
B14: ='Customs Invoice'!B14 -> 0 | K14: B/L No. :
A15: Departure Date: | B15: ='Customs Invoice'!B15 -> 0 | D15: COUNTRY OF ORIGIN: INDONESIA | K15: A/C No. :
A16: Vessel/Flight : | B16: ='Customs Invoice'!B16 -> 0 | D16: From : INDONESIA | K16: C/T No. : | L16: ='Customs Invoice'!L16 -> 1
A17: To : USA | I17: Terms of Payment: | K17: 30 Day's Net
B19: BOX 1 = GOLD JEWELRY
B20: No | C20: ID Code | D20: USA harmonized code | E20: Item | F20: ID | G20: Qty/Pcs,Pair | I20: N.Weight | J20: G.Weight | K20: Jumlah Carton
B21: ='Customs Invoice'!B21 -> 1 | C21: ='Customs Invoice'!C21 -> #N/A | D21: ='Customs Invoice'!D21 -> #N/A | E21: ='Customs Invoice'!E21 -> #N/A | G21: ='Customs Invoice'!G21 -> 0 | H21: ='Customs Invoice'!H21 -> #N/A | I21: ='Customs Invoice'!I21 -> 0 | J21: ='Customs Invoice'!J21 -> #DIV/0! | K21: 1
B22: ='Customs Invoice'!B22 -> 2 | C22: ='Customs Invoice'!C22 -> #N/A | D22: ='Customs Invoice'!D22 -> #N/A | E22: ='Customs Invoice'!E22 -> #N/A | G22: ='Customs Invoice'!G22 -> 0 | H22: ='Customs Invoice'!H22 -> #N/A | I22: ='Customs Invoice'!I22 -> 0 | J22: ='Customs Invoice'!J22 -> 0
B23: ='Customs Invoice'!B23 -> 3 | C23: ='Customs Invoice'!C23 -> #N/A | D23: ='Customs Invoice'!D23 -> #N/A | E23: ='Customs Invoice'!E23 -> #N/A | G23: ='Customs Invoice'!G23 -> 0 | H23: ='Customs Invoice'!H23 -> #N/A | I23: ='Customs Invoice'!I23 -> 0 | J23: ='Customs Invoice'!J23 -> 0
B24: ='Customs Invoice'!B24 -> 4 | C24: ='Customs Invoice'!C24 -> #N/A | D24: ='Customs Invoice'!D24 -> #N/A | E24: ='Customs Invoice'!E24 -> #N/A | G24: ='Customs Invoice'!G24 -> 0 | H24: ='Customs Invoice'!H24 -> #N/A | I24: ='Customs Invoice'!I24 -> 0 | J24: ='Customs Invoice'!J24 -> 0
B25: ='Customs Invoice'!B25 -> 5 | C25: ='Customs Invoice'!C25 -> #N/A | D25: ='Customs Invoice'!D25 -> #N/A | E25: ='Customs Invoice'!E25 -> #N/A | G25: ='Customs Invoice'!G25 -> 0 | H25: ='Customs Invoice'!H25 -> #N/A | I25: ='Customs Invoice'!I25 -> 0 | J25: ='Customs Invoice'!J25 -> 0
B26: ='Customs Invoice'!B26 -> 6 | C26: ='Customs Invoice'!C26 -> #N/A | D26: ='Customs Invoice'!D26 -> #N/A | E26: ='Customs Invoice'!E26 -> #N/A | G26: ='Customs Invoice'!G26 -> 0 | H26: ='Customs Invoice'!H26 -> #N/A | I26: ='Customs Invoice'!I26 -> 0 | J26: ='Customs Invoice'!J26 -> 0
B27: ='Customs Invoice'!B27 -> 7 | C27: ='Customs Invoice'!C27 -> #N/A | D27: ='Customs Invoice'!D27 -> #N/A | E27: ='Customs Invoice'!E27 -> #N/A | G27: ='Customs Invoice'!G27 -> 0 | H27: ='Customs Invoice'!H27 -> #N/A | I27: ='Customs Invoice'!I27 -> 0 | J27: ='Customs Invoice'!J27 -> 0
B28: ='Customs Invoice'!B28 -> 8 | C28: ='Customs Invoice'!C28 -> #N/A | D28: ='Customs Invoice'!D28 -> #N/A | E28: ='Customs Invoice'!E28 -> #N/A | G28: ='Customs Invoice'!G28 -> 0 | H28: ='Customs Invoice'!H28 -> #N/A | I28: ='Customs Invoice'!I28 -> 0 | J28: ='Customs Invoice'!J28 -> 0
B29: ='Customs Invoice'!B29 -> 9 | C29: ='Customs Invoice'!C29 -> #N/A | D29: ='Customs Invoice'!D29 -> #N/A | E29: ='Customs Invoice'!E29 -> #N/A | G29: ='Customs Invoice'!G29 -> 0 | H29: ='Customs Invoice'!H29 -> #N/A | I29: ='Customs Invoice'!I29 -> 0 | J29: ='Customs Invoice'!J29 -> 0
B30: ='Customs Invoice'!B30 -> 10 | C30: ='Customs Invoice'!C30 -> #N/A | D30: ='Customs Invoice'!D30 -> #N/A | E30: ='Customs Invoice'!E30 -> #N/A | G30: ='Customs Invoice'!G30 -> 0 | H30: ='Customs Invoice'!H30 -> #N/A | I30: ='Customs Invoice'!I30 -> 0 | J30: ='Customs Invoice'!J30 -> 0
B31: ='Customs Invoice'!B31 -> 11 | C31: ='Customs Invoice'!C31 -> #N/A | D31: ='Customs Invoice'!D31 -> #N/A | E31: ='Customs Invoice'!E31 -> #N/A | G31: ='Customs Invoice'!G31 -> 0 | H31: ='Customs Invoice'!H31 -> #N/A | I31: ='Customs Invoice'!I31 -> 0 | J31: ='Customs Invoice'!J31 -> 0
B32: ='Customs Invoice'!B32 -> 12 | C32: ='Customs Invoice'!C32 -> #N/A | D32: ='Customs Invoice'!D32 -> #N/A | E32: ='Customs Invoice'!E32 -> #N/A | G32: ='Customs Invoice'!G32 -> 0 | H32: ='Customs Invoice'!H32 -> #N/A | I32: ='Customs Invoice'!I32 -> 0 | J32: ='Customs Invoice'!J32 -> 0
B33: ='Customs Invoice'!B33 -> 13 | C33: ='Customs Invoice'!C33 -> #N/A | D33: ='Customs Invoice'!D33 -> #N/A | E33: ='Customs Invoice'!E33 -> #N/A | G33: ='Customs Invoice'!G33 -> 0 | H33: ='Customs Invoice'!H33 -> #N/A | I33: ='Customs Invoice'!I33 -> 0 | J33: ='Customs Invoice'!J33 -> 0
... B40: ='Customs Invoice'!B40 -> 20 | C40: ='Customs Invoice'!C40 -> #N/A | D40: ='Customs Invoice'!D40 -> #N/A | E40: ='Customs Invoice'!E40 -> #N/A | G40: ='Customs Invoice'!G40 -> 0 | H40: ='Customs Invoice'!H40 -> #N/A | I40: ='Customs Invoice'!I40 -> 0 | J40: ='Customs Invoice'!J40 -> 0
E41: TOTAL | G41: =SUM(G21:G40) -> 0 | I41: =SUM(I21:I40) -> 0 | J41: =SUM(J21:J40) -> #DIV/0! | K41: =SUM(K21) -> 1
B43: BOX 2 = GOLD JEWELRY
B44: No | C44: ID Code | D44: USA harmonized code | E44: Item | F44: ID | G44: Qty/Pcs,Pair | I44: N.Weight | J44: G.Weight | K44: Jumlah Carton
B45: ='Customs Invoice'!B45 -> 0 | C45: ='Customs Invoice'!C45 -> #N/A | D45: ='Customs Invoice'!D45 -> #N/A | E45: ='Customs Invoice'!E45 -> #N/A | G45: ='Customs Invoice'!G45 -> 0 | H45: ='Customs Invoice'!H45 -> #N/A | I45: ='Customs Invoice'!I45 -> 0 | J45: ='Customs Invoice'!J45 -> 0 | K45: 1
B46: ='Customs Invoice'!B46 -> 0 | C46: ='Customs Invoice'!C46 -> #N/A | D46: ='Customs Invoice'!D46 -> #N/A | E46: ='Customs Invoice'!E46 -> #N/A | G46: ='Customs Invoice'!G46 -> 0 | H46: ='Customs Invoice'!H46 -> #N/A | I46: ='Customs Invoice'!I46 -> 0 | J46: ='Customs Invoice'!J46 -> 0
B47: ='Customs Invoice'!B47 -> 0 | C47: ='Customs Invoice'!C47 -> #N/A | D47: ='Customs Invoice'!D47 -> #N/A | E47: ='Customs Invoice'!E47 -> #N/A | G47: ='Customs Invoice'!G47 -> 0 | H47: ='Customs Invoice'!H47 -> #N/A | I47: ='Customs Invoice'!I47 -> 0 | J47: ='Customs Invoice'!J47 -> 0
B48: ='Customs Invoice'!B48 -> 0 | C48: ='Customs Invoice'!C48 -> #N/A | D48: ='Customs Invoice'!D48 -> #N/A | E48: ='Customs Invoice'!E48 -> #N/A | G48: ='Customs Invoice'!G48 -> 0 | H48: ='Customs Invoice'!H48 -> #N/A | I48: ='Customs Invoice'!I48 -> 0 | J48: ='Customs Invoice'!J48 -> 0
...

Sheet US Customs Invoice
A1: PT. VERONIQUE INDONESIA
A2: Jl. Raya Purwonegoro Rt. 007/003, Purwonegoro, Banjarnegara, Jawa Tengah, Zip Code : 53472, INDONESIA
A3: INVOICE
A4: Seller: | B4: PT. VERONIQUE INDONESIA | I4: Invoice No. & Date : | J4: ='Customs Invoice'!K4 -> 0 | K4: ='Customs Invoice'!L4 -> 0
B5: Jl. Raya Purwonegoro Rt. 007/003 Purwonegoro Banjarnegara | I5: L/C No. & Date) :
B6: Jawa Tengah Zip Code : 53472 INDONESIA | I6: ='Customs Invoice'!I6 -> BILL TO : | J6: ='Customs Invoice'!K6 -> 0 | L6: NEW MERCHANDISE
B7: NPWP : 0315202689-529000 | J7: ='Customs Invoice'!K7 -> 0
B8: Tel : 62-286-598-8594 Fax : 62-286-598-8650 | J8: ='Customs Invoice'!K8 -> 0
A9: Consignee: | B9: ='Customs Invoice'!B9 -> 0 | J9: ='Customs Invoice'!K9 -> 0
B10: ='Customs Invoice'!B10 -> 0 | J10: ='Customs Invoice'!K10 -> 0
B11: ='Customs Invoice'!B11 -> 0 | J11: ='Customs Invoice'!K11 -> 0
B12: ='Customs Invoice'!B12 -> 0 | I12: "GSP eligible Article"
B13: ='Customs Invoice'!B13 -> 0 | I13: Other References: | J13: Country of Origin : | K13: INDONESIA
B14: ='Customs Invoice'!B14 -> 0 | J14: B/L No. :
A15: Departure Date: | B15: ='Customs Invoice'!B15 -> 0 | D15: COUNTRY OF ORIGIN: INDONESIA | J15: A/C No. :
A16: Vessel/Flight : | B16: ='Customs Invoice'!B16 -> 0 | D16: From : INDONESIA | J16: C/T No. : | K16: ='Customs Invoice'!L16 -> 1
A17: ='Customs Invoice'!A17 -> To : | I17: Terms of Payment: | J17: 30 Day's Net
B18: =CONCATENATE("PT Veronique to US_",LEFT('Customs Invoice'!K4,13)," Customs Invoice_New Merchandise") -> PT Veronique to US_ Customs Invoice_New Merchandise
B19: BOX 1 = GOLD JEWELRY
B20: No | C20: Manufacturer ID code | D20: USA HTS code | E20: Item description | F20: ID | G20: QTY (Pcs, pairs) | I20: N.Weight | J20: G.Weight | K20: Total value
B21: ='Customs Invoice'!B21 -> 1 | C21: ='Customs Invoice'!C21 -> #N/A | D21: =VLOOKUP(F21,Sheet2!$A$2:$D$31,4,0) -> #N/A | E21: ='Customs Invoice'!E21 -> #N/A | F21: ='Customs Invoice'!F21 -> 0 | G21: ='Customs Invoice'!G21 -> 0 | H21: ='Customs Invoice'!H21 -> #N/A | I21: ='Customs Invoice'!I21 -> 0 | J21: ='Customs Invoice'!J21 -> #DIV/0! | K21: ='Customs Invoice'!P21 -> 0
D22: =VLOOKUP(F22,Sheet2!$A$2:$D$31,4,0) -> #N/A | F22: =F21&1 -> 01
B23: ='Customs Invoice'!B22 -> 2 | C23: ='Customs Invoice'!C22 -> #N/A | D23: =VLOOKUP(F23,Sheet2!$A$2:$D$31,4,0) -> #N/A | E23: ='Customs Invoice'!E22 -> #N/A | F23: ='Customs Invoice'!F22 -> 0 | G23: ='Customs Invoice'!G22 -> 0 | H23: ='Customs Invoice'!H22 -> #N/A | I23: ='Customs Invoice'!I22 -> 0 | J23: ='Customs Invoice'!J22 -> 0 | K23: ='Customs Invoice'!P22 -> 0
D24: =VLOOKUP(F24,Sheet2!$A$2:$D$31,4,0) -> #N/A | F24: =F23&1 -> 01
B25: ='Customs Invoice'!B23 -> 3 | C25: ='Customs Invoice'!C23 -> #N/A | D25: =VLOOKUP(F25,Sheet2!$A$2:$D$31,4,0) -> #N/A | E25: ='Customs Invoice'!E23 -> #N/A | F25: ='Customs Invoice'!F23 -> 0 | G25: ='Customs Invoice'!G23 -> 0 | H25: ='Customs Invoice'!H23 -> #N/A | I25: ='Customs Invoice'!I23 -> 0 | J25: ='Customs Invoice'!J23 -> 0 | K25: ='Customs Invoice'!P23 -> 0
D26: =VLOOKUP(F26,Sheet2!$A$2:$D$31,4,0) -> #N/A | F26: =F25&1 -> 01
B27: ='Customs Invoice'!B24 -> 4 | C27: ='Customs Invoice'!C24 -> #N/A | D27: =VLOOKUP(F27,Sheet2!$A$2:$D$31,4,0) -> #N/A | E27: ='Customs Invoice'!E24 -> #N/A | F27: ='Customs Invoice'!F24 -> 0 | G27: ='Customs Invoice'!G24 -> 0 | H27: ='Customs Invoice'!H24 -> #N/A | I27: ='Customs Invoice'!I24 -> 0 | J27: ='Customs Invoice'!J24 -> 0 | K27: ='Customs Invoice'!P24 -> 0
D28: =VLOOKUP(F28,Sheet2!$A$2:$D$31,4,0) -> #N/A | F28: =F27&1 -> 01
B29: ='Customs Invoice'!B25 -> 5 | C29: ='Customs Invoice'!C25 -> #N/A | D29: =VLOOKUP(F29,Sheet2!$A$2:$D$31,4,0) -> #N/A | E29: ='Customs Invoice'!E25 -> #N/A | F29: ='Customs Invoice'!F25 -> 0 | G29: ='Customs Invoice'!G25 -> 0 | H29: ='Customs Invoice'!H25 -> #N/A | I29: ='Customs Invoice'!I25 -> 0 | J29: ='Customs Invoice'!J25 -> 0 | K29: ='Customs Invoice'!P25 -> 0
D30: =VLOOKUP(F30,Sheet2!$A$2:$D$31,4,0) -> #N/A | F30: =F29&1 -> 01
B31: ='Customs Invoice'!B26 -> 6 | C31: ='Customs Invoice'!C26 -> #N/A | D31: =VLOOKUP(F31,Sheet2!$A$2:$D$31,4,0) -> #N/A | E31: ='Customs Invoice'!E26 -> #N/A | F31: ='Customs Invoice'!F26 -> 0 | G31: ='Customs Invoice'!G26 -> 0 | H31: ='Customs Invoice'!H26 -> #N/A | I31: ='Customs Invoice'!I26 -> 0 | J31: ='Customs Invoice'!J26 -> 0 | K31: ='Customs Invoice'!P26 -> 0
D32: =VLOOKUP(F32,Sheet2!$A$2:$D$31,4,0) -> #N/A | F32: =F31&1 -> 01
B33: ='Customs Invoice'!B27 -> 7 | C33: ='Customs Invoice'!C27 -> #N/A | D33: =VLOOKUP(F33,Sheet2!$A$2:$D$31,4,0) -> #N/A | E33: ='Customs Invoice'!E27 -> #N/A | F33: ='Customs Invoice'!F27 -> 0 | G33: ='Customs Invoice'!G27 -> 0 | H33: ='Customs Invoice'!H27 -> #N/A | I33: ='Customs Invoice'!I27 -> 0 | J33: ='Customs Invoice'!J27 -> 0 | K33: ='Customs Invoice'!P27 -> 0
D34: =VLOOKUP(F34,Sheet2!$A$2:$D$31,4,0) -> #N/A | F34: =F33&1 -> 01
B35: ='Customs Invoice'!B28 -> 8 | C35: ='Customs Invoice'!C28 -> #N/A | D35: =VLOOKUP(F35,Sheet2!$A$2:$D$31,4,0) -> #N/A | E35: ='Customs Invoice'!E28 -> #N/A | F35: ='Customs Invoice'!F28 -> 0 | G35: ='Customs Invoice'!G28 -> 0 | H35: ='Customs Invoice'!H28 -> #N/A | I35: ='Customs Invoice'!I28 -> 0 | J35: ='Customs Invoice'!J28 -> 0 | K35: ='Customs Invoice'!P28 -> 0
D36: =VLOOKUP(F36,Sheet2!$A$2:$D$31,4,0) -> #N/A | F36: =F35&1 -> 01
B37: ='Customs Invoice'!B29 -> 9 | C37: ='Customs Invoice'!C29 -> #N/A | D37: =VLOOKUP(F37,Sheet2!$A$2:$D$31,4,0) -> #N/A | E37: ='Customs Invoice'!E29 -> #N/A | F37: ='Customs Invoice'!F29 -> 0 | G37: ='Customs Invoice'!G29 -> 0 | H37: ='Customs Invoice'!H29 -> #N/A | I37: ='Customs Invoice'!I29 -> 0 | J37: ='Customs Invoice'!J29 -> 0 | K37: ='Customs Invoice'!P29 -> 0
D38: =VLOOKUP(F38,Sheet2!$A$2:$D$31,4,0) -> #N/A | F38: =F37&1 -> 01
B39: ='Customs Invoice'!B30 -> 10 | C39: ='Customs Invoice'!C30 -> #N/A | D39: =VLOOKUP(F39,Sheet2!$A$2:$D$31,4,0) -> #N/A | E39: ='Customs Invoice'!E30 -> #N/A | F39: ='Customs Invoice'!F30 -> - | G39: ='Customs Invoice'!G30 -> 0 | H39: ='Customs Invoice'!H30 -> #N/A | I39: ='Customs Invoice'!I30 -> 0 | J39: ='Customs Invoice'!J30 -> 0 | K39: ='Customs Invoice'!P30 -> 0
D40: =VLOOKUP(F40,Sheet2!$A$2:$D$31,4,0) -> #N/A | F40: =F39&1 -> -1
...

Sheet US Customs Invoice GOLD
A1: PT. VERONIQUE INDONESIA
A2: Jl. Raya Purwonegoro Rt. 007/003, Purwonegoro, Banjarnegara, Jawa Tengah, Zip Code : 53472, INDONESIA
A3: INVOICE
A4: Seller: | B4: PT. VERONIQUE INDONESIA | I4: Invoice No. & Date : | J4: ='Customs Invoice'!K4 -> 0 | K4: ='Customs Invoice'!L4 -> 0
B5: Jl. Raya Purwonegoro Rt. 007/003 Purwonegoro Banjarnegara | I5: L/C No. & Date) :
B6: Jawa Tengah Zip Code : 53472 INDONESIA | I6: ='Customs Invoice'!I6 -> BILL TO : | J6: ='Customs Invoice'!K6 -> 0 | L6: NEW MERCHANDISE
B7: NPWP : 0315202689-529000 | J7: ='Customs Invoice'!K7 -> 0
B8: Tel : 62-286-598-8594 Fax : 62-286-598-8650 | J8: ='Customs Invoice'!K8 -> 0
A9: Consignee: | B9: ='Customs Invoice'!B9 -> 0 | J9: ='Customs Invoice'!K9 -> 0
B10: ='Customs Invoice'!B10 -> 0 | J10: ='Customs Invoice'!K10 -> 0
B11: ='Customs Invoice'!B11 -> 0 | J11: ='Customs Invoice'!K11 -> 0
B12: ='Customs Invoice'!B12 -> 0 | I12: "GSP eligible Article"
B13: ='Customs Invoice'!B13 -> 0 | I13: Other References: | J13: Country of Origin : | K13: INDONESIA
B14: ='Customs Invoice'!B14 -> 0 | J14: B/L No. :
A15: Departure Date: | B15: ='Customs Invoice'!B15 -> 0 | D15: COUNTRY OF ORIGIN: INDONESIA | J15: A/C No. :
A16: Vessel/Flight : | B16: ='Customs Invoice'!B16 -> 0 | D16: From : INDONESIA | J16: C/T No. : | K16: ='Customs Invoice'!L16 -> 1
A17: ='Customs Invoice'!A17 -> To : | I17: Terms of Payment: | J17: 30 Day's Net
B18: =CONCATENATE("PT Veronique to US_",LEFT('Customs Invoice'!K4,13)," Customs Invoice_New Merchandise") -> PT Veronique to US_ Customs Invoice_New Merchandise
B19: BOX 1 = GOLD JEWELRY
B20: No | C20: Manufacturer ID code | D20: USA HTS code | E20: Item description | F20: ID | G20: QTY (Pcs, pairs) | I20: N.Weight | J20: G.Weight | K20: Gold Value
B21: ='Customs Invoice'!B21 -> 1 | C21: ='Customs Invoice'!C21 -> #N/A | D21: =VLOOKUP(F21,Sheet2!$A$2:$D$31,4,0) -> #N/A | E21: ='Customs Invoice'!E21 -> #N/A | F21: ='Customs Invoice'!F21 -> 0 | G21: ='Customs Invoice'!G21 -> 0 | H21: ='Customs Invoice'!H21 -> #N/A | I21: ='Customs Invoice'!I21 -> 0 | J21: ='Customs Invoice'!J21 -> #DIV/0! | K21: ='Customs Invoice'!O21 -> 0
D22: =VLOOKUP(F22,Sheet2!$A$2:$D$31,4,0) -> #N/A | F22: =F21&1 -> 01
B23: ='Customs Invoice'!B22 -> 2 | C23: ='Customs Invoice'!C22 -> #N/A | D23: =VLOOKUP(F23,Sheet2!$A$2:$D$31,4,0) -> #N/A | E23: ='Customs Invoice'!E22 -> #N/A | F23: ='Customs Invoice'!F22 -> 0 | G23: ='Customs Invoice'!G22 -> 0 | H23: ='Customs Invoice'!H22 -> #N/A | I23: ='Customs Invoice'!I22 -> 0 | J23: ='Customs Invoice'!J22 -> 0 | K23: ='Customs Invoice'!O22 -> 0
D24: =VLOOKUP(F24,Sheet2!$A$2:$D$31,4,0) -> #N/A | F24: =F23&1 -> 01
B25: ='Customs Invoice'!B23 -> 3 | C25: ='Customs Invoice'!C23 -> #N/A | D25: =VLOOKUP(F25,Sheet2!$A$2:$D$31,4,0) -> #N/A | E25: ='Customs Invoice'!E23 -> #N/A | F25: ='Customs Invoice'!F23 -> 0 | G25: ='Customs Invoice'!G23 -> 0 | H25: ='Customs Invoice'!H23 -> #N/A | I25: ='Customs Invoice'!I23 -> 0 | J25: ='Customs Invoice'!J23 -> 0 | K25: ='Customs Invoice'!O23 -> 0
D26: =VLOOKUP(F26,Sheet2!$A$2:$D$31,4,0) -> #N/A | F26: =F25&1 -> 01
B27: ='Customs Invoice'!B24 -> 4 | C27: ='Customs Invoice'!C24 -> #N/A | D27: =VLOOKUP(F27,Sheet2!$A$2:$D$31,4,0) -> #N/A | E27: ='Customs Invoice'!E24 -> #N/A | F27: ='Customs Invoice'!F24 -> 0 | G27: ='Customs Invoice'!G24 -> 0 | H27: ='Customs Invoice'!H24 -> #N/A | I27: ='Customs Invoice'!I24 -> 0 | J27: ='Customs Invoice'!J24 -> 0 | K27: ='Customs Invoice'!O24 -> 0
D28: =VLOOKUP(F28,Sheet2!$A$2:$D$31,4,0) -> #N/A | F28: =F27&1 -> 01
B29: ='Customs Invoice'!B25 -> 5 | C29: ='Customs Invoice'!C25 -> #N/A | D29: =VLOOKUP(F29,Sheet2!$A$2:$D$31,4,0) -> #N/A | E29: ='Customs Invoice'!E25 -> #N/A | F29: ='Customs Invoice'!F25 -> 0 | G29: ='Customs Invoice'!G25 -> 0 | H29: ='Customs Invoice'!H25 -> #N/A | I29: ='Customs Invoice'!I25 -> 0 | J29: ='Customs Invoice'!J25 -> 0 | K29: ='Customs Invoice'!O25 -> 0
D30: =VLOOKUP(F30,Sheet2!$A$2:$D$31,4,0) -> #N/A | F30: =F29&1 -> 01
B31: ='Customs Invoice'!B26 -> 6 | C31: ='Customs Invoice'!C26 -> #N/A | D31: =VLOOKUP(F31,Sheet2!$A$2:$D$31,4,0) -> #N/A | E31: ='Customs Invoice'!E26 -> #N/A | F31: ='Customs Invoice'!F26 -> 0 | G31: ='Customs Invoice'!G26 -> 0 | H31: ='Customs Invoice'!H26 -> #N/A | I31: ='Customs Invoice'!I26 -> 0 | J31: ='Customs Invoice'!J26 -> 0 | K31: ='Customs Invoice'!O26 -> 0
D32: =VLOOKUP(F32,Sheet2!$A$2:$D$31,4,0) -> #N/A | F32: =F31&1 -> 01
B33: ='Customs Invoice'!B27 -> 7 | C33: ='Customs Invoice'!C27 -> #N/A | D33: =VLOOKUP(F33,Sheet2!$A$2:$D$31,4,0) -> #N/A | E33: ='Customs Invoice'!E27 -> #N/A | F33: ='Customs Invoice'!F27 -> 0 | G33: ='Customs Invoice'!G27 -> 0 | H33: ='Customs Invoice'!H27 -> #N/A | I33: ='Customs Invoice'!I27 -> 0 | J33: ='Customs Invoice'!J27 -> 0 | K33: ='Customs Invoice'!O27 -> 0
D34: =VLOOKUP(F34,Sheet2!$A$2:$D$31,4,0) -> #N/A | F34: =F33&1 -> 01
B35: ='Customs Invoice'!B28 -> 8 | C35: ='Customs Invoice'!C28 -> #N/A | D35: =VLOOKUP(F35,Sheet2!$A$2:$D$31,4,0) -> #N/A | E35: ='Customs Invoice'!E28 -> #N/A | F35: ='Customs Invoice'!F28 -> 0 | G35: ='Customs Invoice'!G28 -> 0 | H35: ='Customs Invoice'!H28 -> #N/A | I35: ='Customs Invoice'!I28 -> 0 | J35: ='Customs Invoice'!J28 -> 0 | K35: ='Customs Invoice'!O28 -> 0
D36: =VLOOKUP(F36,Sheet2!$A$2:$D$31,4,0) -> #N/A | F36: =F35&1 -> 01
B37: ='Customs Invoice'!B29 -> 9 | C37: ='Customs Invoice'!C29 -> #N/A | D37: =VLOOKUP(F37,Sheet2!$A$2:$D$31,4,0) -> #N/A | E37: ='Customs Invoice'!E29 -> #N/A | F37: ='Customs Invoice'!F29 -> 0 | G37: ='Customs Invoice'!G29 -> 0 | H37: ='Customs Invoice'!H29 -> #N/A | I37: ='Customs Invoice'!I29 -> 0 | J37: ='Customs Invoice'!J29 -> 0 | K37: ='Customs Invoice'!O29 -> 0
D38: =VLOOKUP(F38,Sheet2!$A$2:$D$31,4,0) -> #N/A | F38: =F37&1 -> 01
B39: ='Customs Invoice'!B30 -> 10 | C39: ='Customs Invoice'!C30 -> #N/A | D39: =VLOOKUP(F39,Sheet2!$A$2:$D$31,4,0) -> #N/A | E39: ='Customs Invoice'!E30 -> #N/A | F39: ='Customs Invoice'!F30 -> - | G39: ='Customs Invoice'!G30 -> 0 | H39: ='Customs Invoice'!H30 -> #N/A | I39: ='Customs Invoice'!I30 -> 0 | J39: ='Customs Invoice'!J30 -> 0 | K39: ='Customs Invoice'!O30 -> 0
D40: =VLOOKUP(F40,Sheet2!$A$2:$D$31,4,0) -> #N/A | F40: =F39&1 -> -1
...

Sheet US Customs Invoice LABOR
A1: PT. VERONIQUE INDONESIA
A2: Jl. Raya Purwonegoro Rt. 007/003, Purwonegoro, Banjarnegara, Jawa Tengah, Zip Code : 53472, INDONESIA
A3: INVOICE
A4: Seller: | B4: PT. VERONIQUE INDONESIA | I4: Invoice No. & Date : | J4: ='Customs Invoice'!K4 -> 0 | K4: ='Customs Invoice'!L4 -> 0
B5: Jl. Raya Purwonegoro Rt. 007/003 Purwonegoro Banjarnegara | I5: L/C No. & Date) :
B6: Jawa Tengah Zip Code : 53472 INDONESIA | I6: ='Customs Invoice'!I6 -> BILL TO : | J6: ='Customs Invoice'!K6 -> 0 | L6: NEW MERCHANDISE
B7: NPWP : 0315202689-529000 | J7: ='Customs Invoice'!K7 -> 0
B8: Tel : 62-286-598-8594 Fax : 62-286-598-8650 | J8: ='Customs Invoice'!K8 -> 0
A9: Consignee: | B9: ='Customs Invoice'!B9 -> 0 | J9: ='Customs Invoice'!K9 -> 0
B10: ='Customs Invoice'!B10 -> 0 | J10: ='Customs Invoice'!K10 -> 0
B11: ='Customs Invoice'!B11 -> 0 | J11: ='Customs Invoice'!K11 -> 0
B12: ='Customs Invoice'!B12 -> 0 | I12: "GSP eligible Article"
B13: ='Customs Invoice'!B13 -> 0 | I13: Other References: | J13: Country of Origin : | K13: INDONESIA
B14: ='Customs Invoice'!B14 -> 0 | J14: B/L No. :
A15: Departure Date: | B15: ='Customs Invoice'!B15 -> 0 | D15: COUNTRY OF ORIGIN: INDONESIA | J15: A/C No. :
A16: Vessel/Flight : | B16: ='Customs Invoice'!B16 -> 0 | D16: From : INDONESIA | J16: C/T No. : | K16: ='Customs Invoice'!L16 -> 1
A17: ='Customs Invoice'!A17 -> To : | I17: Terms of Payment: | J17: 30 Day's Net
B18: =CONCATENATE("PT Veronique to US_",LEFT('Customs Invoice'!K4,13)," Customs Invoice_New Merchandise") -> PT Veronique to US_ Customs Invoice_New Merchandise
B19: BOX 1 = GOLD JEWELRY
B20: No | C20: Manufacturer ID code | D20: USA HTS code | E20: Item description | F20: ID | G20: QTY (Pcs, pairs) | I20: N.Weight | J20: G.Weight | K20: Manufacturing Value
B21: ='Customs Invoice'!B21 -> 1 | C21: ='Customs Invoice'!C21 -> #N/A | D21: =VLOOKUP(F21,Sheet2!$A$2:$D$31,4,0) -> #N/A | E21: ='Customs Invoice'!E21 -> #N/A | F21: ='Customs Invoice'!F21 -> 0 | G21: ='Customs Invoice'!G21 -> 0 | H21: ='Customs Invoice'!H21 -> #N/A | I21: ='Customs Invoice'!I21 -> 0 | J21: ='Customs Invoice'!J21 -> #DIV/0! | K21: ='Customs Invoice'!M21 -> 0
D22: =VLOOKUP(F22,Sheet2!$A$2:$D$31,4,0) -> #N/A | F22: =F21&1 -> 01
B23: ='Customs Invoice'!B22 -> 2 | C23: ='Customs Invoice'!C22 -> #N/A | D23: =VLOOKUP(F23,Sheet2!$A$2:$D$31,4,0) -> #N/A | E23: ='Customs Invoice'!E22 -> #N/A | F23: ='Customs Invoice'!F22 -> 0 | G23: ='Customs Invoice'!G22 -> 0 | H23: ='Customs Invoice'!H22 -> #N/A | I23: ='Customs Invoice'!I22 -> 0 | J23: ='Customs Invoice'!J22 -> 0 | K23: ='Customs Invoice'!M22 -> 0
D24: =VLOOKUP(F24,Sheet2!$A$2:$D$31,4,0) -> #N/A | F24: =F23&1 -> 01
B25: ='Customs Invoice'!B23 -> 3 | C25: ='Customs Invoice'!C23 -> #N/A | D25: =VLOOKUP(F25,Sheet2!$A$2:$D$31,4,0) -> #N/A | E25: ='Customs Invoice'!E23 -> #N/A | F25: ='Customs Invoice'!F23 -> 0 | G25: ='Customs Invoice'!G23 -> 0 | H25: ='Customs Invoice'!H23 -> #N/A | I25: ='Customs Invoice'!I23 -> 0 | J25: ='Customs Invoice'!J23 -> 0 | K25: ='Customs Invoice'!M23 -> 0
D26: =VLOOKUP(F26,Sheet2!$A$2:$D$31,4,0) -> #N/A | F26: =F25&1 -> 01
B27: ='Customs Invoice'!B24 -> 4 | C27: ='Customs Invoice'!C24 -> #N/A | D27: =VLOOKUP(F27,Sheet2!$A$2:$D$31,4,0) -> #N/A | E27: ='Customs Invoice'!E24 -> #N/A | F27: ='Customs Invoice'!F24 -> 0 | G27: ='Customs Invoice'!G24 -> 0 | H27: ='Customs Invoice'!H24 -> #N/A | I27: ='Customs Invoice'!I24 -> 0 | J27: ='Customs Invoice'!J24 -> 0 | K27: ='Customs Invoice'!M24 -> 0
D28: =VLOOKUP(F28,Sheet2!$A$2:$D$31,4,0) -> #N/A | F28: =F27&1 -> 01
B29: ='Customs Invoice'!B25 -> 5 | C29: ='Customs Invoice'!C25 -> #N/A | D29: =VLOOKUP(F29,Sheet2!$A$2:$D$31,4,0) -> #N/A | E29: ='Customs Invoice'!E25 -> #N/A | F29: ='Customs Invoice'!F25 -> 0 | G29: ='Customs Invoice'!G25 -> 0 | H29: ='Customs Invoice'!H25 -> #N/A | I29: ='Customs Invoice'!I25 -> 0 | J29: ='Customs Invoice'!J25 -> 0 | K29: ='Customs Invoice'!M25 -> 0
D30: =VLOOKUP(F30,Sheet2!$A$2:$D$31,4,0) -> #N/A | F30: =F29&1 -> 01
B31: ='Customs Invoice'!B26 -> 6 | C31: ='Customs Invoice'!C26 -> #N/A | D31: =VLOOKUP(F31,Sheet2!$A$2:$D$31,4,0) -> #N/A | E31: ='Customs Invoice'!E26 -> #N/A | F31: ='Customs Invoice'!F26 -> 0 | G31: ='Customs Invoice'!G26 -> 0 | H31: ='Customs Invoice'!H26 -> #N/A | I31: ='Customs Invoice'!I26 -> 0 | J31: ='Customs Invoice'!J26 -> 0 | K31: ='Customs Invoice'!M26 -> 0
D32: =VLOOKUP(F32,Sheet2!$A$2:$D$31,4,0) -> #N/A | F32: =F31&1 -> 01
B33: ='Customs Invoice'!B27 -> 7 | C33: ='Customs Invoice'!C27 -> #N/A | D33: =VLOOKUP(F33,Sheet2!$A$2:$D$31,4,0) -> #N/A | E33: ='Customs Invoice'!E27 -> #N/A | F33: ='Customs Invoice'!F27 -> 0 | G33: ='Customs Invoice'!G27 -> 0 | H33: ='Customs Invoice'!H27 -> #N/A | I33: ='Customs Invoice'!I27 -> 0 | J33: ='Customs Invoice'!J27 -> 0 | K33: ='Customs Invoice'!M27 -> 0
D34: =VLOOKUP(F34,Sheet2!$A$2:$D$31,4,0) -> #N/A | F34: =F33&1 -> 01
B35: ='Customs Invoice'!B28 -> 8 | C35: ='Customs Invoice'!C28 -> #N/A | D35: =VLOOKUP(F35,Sheet2!$A$2:$D$31,4,0) -> #N/A | E35: ='Customs Invoice'!E28 -> #N/A | F35: ='Customs Invoice'!F28 -> 0 | G35: ='Customs Invoice'!G28 -> 0 | H35: ='Customs Invoice'!H28 -> #N/A | I35: ='Customs Invoice'!I28 -> 0 | J35: ='Customs Invoice'!J28 -> 0 | K35: ='Customs Invoice'!M28 -> 0
D36: =VLOOKUP(F36,Sheet2!$A$2:$D$31,4,0) -> #N/A | F36: =F35&1 -> 01
B37: ='Customs Invoice'!B29 -> 9 | C37: ='Customs Invoice'!C29 -> #N/A | D37: =VLOOKUP(F37,Sheet2!$A$2:$D$31,4,0) -> #N/A | E37: ='Customs Invoice'!E29 -> #N/A | F37: ='Customs Invoice'!F29 -> 0 | G37: ='Customs Invoice'!G29 -> 0 | H37: ='Customs Invoice'!H29 -> #N/A | I37: ='Customs Invoice'!I29 -> 0 | J37: ='Customs Invoice'!J29 -> 0 | K37: ='Customs Invoice'!M29 -> 0
D38: =VLOOKUP(F38,Sheet2!$A$2:$D$31,4,0) -> #N/A | F38: =F37&1 -> 01
B39: ='Customs Invoice'!B30 -> 10 | C39: ='Customs Invoice'!C30 -> #N/A | D39: =VLOOKUP(F39,Sheet2!$A$2:$D$31,4,0) -> #N/A | E39: ='Customs Invoice'!E30 -> #N/A | F39: ='Customs Invoice'!F30 -> - | G39: ='Customs Invoice'!G30 -> 0 | H39: ='Customs Invoice'!H30 -> #N/A | I39: ='Customs Invoice'!I30 -> 0 | J39: ='Customs Invoice'!J30 -> 0 | K39: ='Customs Invoice'!M30 -> 0
D40: =VLOOKUP(F40,Sheet2!$A$2:$D$31,4,0) -> #N/A | F40: =F39&1 -> -1
...

Sheet Customs Invoice NON MAKLON
A1: PT. VERONIQUE INDONESIA
A2: Jl. Raya Purwonegoro Rt. 007/003, Purwonegoro, Banjarnegara, Jawa Tengah, Zip Code : 53472, INDONESIA
A3: INVOICE
A4: Seller: | B4: PT. VERONIQUE INDONESIA | I4: Invoice No. & Date : | K4: ='Customs Invoice'!K4 -> 0 | L4: ='Customs Invoice'!L4 -> 0
B5: Jl. Raya Purwonegoro Rt. 007/003 Purwonegoro Banjarnegara | I5: L/C No. & Date) :
B6: Jawa Tengah Zip Code : 53472 INDONESIA | I6: BILL TO : | K6: ='Customs Invoice'!K6 -> 0
B7: NPWP : 0315202689-529000 | K7: ='Customs Invoice'!K7 -> 0
B8: Tel : 62-286-598-8594 Fax : 62-286-598-8650 | K8: ='Customs Invoice'!K8 -> 0
A9: Consignee: | B9: ='Customs Invoice'!B9 -> 0 | K9: ='Customs Invoice'!K9 -> 0
B10: ='Customs Invoice'!B10 -> 0 | K10: NEW MERCHANDISE
B11: ='Customs Invoice'!B11 -> 0
B12: ='Customs Invoice'!B12 -> 0 | I12: "GSP eligible Article"
B13: ='Customs Invoice'!B13 -> 0 | I13: Other References: | K13: Country of Origin : | L13: INDONESIA
B14: ='Customs Invoice'!B14 -> 0 | K14: B/L No. :
A15: Departure Date: | B15: ='Customs Invoice'!B15 -> 0 | D15: COUNTRY OF ORIGIN: INDONESIA | K15: A/C No. :
A16: Vessel/Flight : | B16: ='Customs Invoice'!B16 -> 0 | D16: From : INDONESIA | K16: C/T No. : | L16: 1
A17: To : | B17: ='Customs Invoice'!B17 -> 0 | I17: Terms of Payment: | K17: 30 Day's Net
B19: BOX 1 = GOLD JEWELRY
B20: No | C20: ID Code | D20: USA harmonized code | E20: Item | F20: ID | G20: Qty/Pcs,Pair | I20: N.Weight | J20: G.Weight | K20: Unit Value | L20: Total Value | M20: Manufacturing Cost (nilai maklon) | N20: Dia Value | O20: Gold Value | P20: Manufacturing + Dia + Gold for US | R20: Total Value | S20: N.Weight
B21: 1 | C21: =CONCATENATE("FGG-",MID(E21,1,3),MID(E21,10,1),"-ASU") -> #N/A | D21: ='Customs Invoice'!D21 -> #N/A | E21: ='Customs Invoice'!E21 -> #N/A | F21: ='Customs Invoice'!F21 -> 0 | G21: ='Customs Invoice'!G21 -> 0 | H21: ='Customs Invoice'!H21 -> #N/A | I21: ='Customs Invoice'!I21 -> 0 | J21: ='Customs Invoice'!J21 -> #DIV/0! | K21: =L21/G21 -> #DIV/0! | L21: ='Customs Invoice'!L21 -> 0 | R21: =L21 -> 0 | S21: =I21 -> 0
B22: 2 | C22: =CONCATENATE("FGG-",MID(E22,1,3),MID(E22,10,1),"-ASU") -> #N/A | D22: ='Customs Invoice'!D22 -> #N/A | E22: ='Customs Invoice'!E22 -> #N/A | F22: ='Customs Invoice'!F22 -> 0 | G22: ='Customs Invoice'!G22 -> 0 | H22: ='Customs Invoice'!H22 -> #N/A | I22: ='Customs Invoice'!I22 -> 0 | J22: ='Customs Invoice'!J22 -> 0 | K22: =L22/G22 -> #DIV/0! | L22: ='Customs Invoice'!L22 -> 0 | R22: =L22 -> 0 | S22: =I22 -> 0
B23: 3 | C23: =CONCATENATE("FGG-",MID(E23,1,3),MID(E23,10,1),"-ASU") -> #N/A | D23: ='Customs Invoice'!D23 -> #N/A | E23: ='Customs Invoice'!E23 -> #N/A | F23: ='Customs Invoice'!F23 -> 0 | G23: ='Customs Invoice'!G23 -> 0 | H23: ='Customs Invoice'!H23 -> #N/A | I23: ='Customs Invoice'!I23 -> 0 | J23: ='Customs Invoice'!J23 -> 0 | K23: =L23/G23 -> #DIV/0! | L23: ='Customs Invoice'!L23 -> 0 | R23: =L23 -> 0 | S23: =I23 -> 0
B24: 4 | C24: =CONCATENATE("FGG-",MID(E24,1,3),MID(E24,10,1),"-ASU") -> #N/A | D24: ='Customs Invoice'!D24 -> #N/A | E24: ='Customs Invoice'!E24 -> #N/A | F24: ='Customs Invoice'!F24 -> 0 | G24: ='Customs Invoice'!G24 -> 0 | H24: ='Customs Invoice'!H24 -> #N/A | I24: ='Customs Invoice'!I24 -> 0 | J24: ='Customs Invoice'!J24 -> 0 | K24: =L24/G24 -> #DIV/0! | L24: ='Customs Invoice'!L24 -> 0 | R24: =L24 -> 0 | S24: =I24 -> 0
B25: 5 | C25: =CONCATENATE("FGG-",MID(E25,1,3),MID(E25,10,1),"-ASU") -> #N/A | D25: ='Customs Invoice'!D25 -> #N/A | E25: ='Customs Invoice'!E25 -> #N/A | F25: ='Customs Invoice'!F25 -> 0 | G25: ='Customs Invoice'!G25 -> 0 | H25: ='Customs Invoice'!H25 -> #N/A | I25: ='Customs Invoice'!I25 -> 0 | J25: ='Customs Invoice'!J25 -> 0 | K25: =L25/G25 -> #DIV/0! | L25: ='Customs Invoice'!L25 -> 0 | R25: =L25 -> 0 | S25: =I25 -> 0
B26: 6 | C26: =CONCATENATE("FGG-",MID(E26,1,3),MID(E26,10,1),"-ASU") -> #N/A | D26: ='Customs Invoice'!D26 -> #N/A | E26: ='Customs Invoice'!E26 -> #N/A | F26: ='Customs Invoice'!F26 -> 0 | G26: ='Customs Invoice'!G26 -> 0 | H26: ='Customs Invoice'!H26 -> #N/A | I26: ='Customs Invoice'!I26 -> 0 | J26: ='Customs Invoice'!J26 -> 0 | K26: =L26/G26 -> #DIV/0! | L26: ='Customs Invoice'!L26 -> 0 | R26: =L26 -> 0 | S26: =I26 -> 0
B27: 7 | C27: =CONCATENATE("FGG-",MID(E27,1,3),MID(E27,10,1),"-ASU") -> #N/A | D27: ='Customs Invoice'!D27 -> #N/A | E27: ='Customs Invoice'!E27 -> #N/A | F27: ='Customs Invoice'!F27 -> 0 | G27: ='Customs Invoice'!G27 -> 0 | H27: ='Customs Invoice'!H27 -> #N/A | I27: ='Customs Invoice'!I27 -> 0 | J27: ='Customs Invoice'!J27 -> 0 | K27: =L27/G27 -> #DIV/0! | L27: ='Customs Invoice'!L27 -> 0 | R27: =L27 -> 0 | S27: =I27 -> 0
B28: 8 | C28: =CONCATENATE("FGG-",MID(E28,1,3),MID(E28,10,1),"-ASU") -> #N/A | D28: ='Customs Invoice'!D28 -> #N/A | E28: ='Customs Invoice'!E28 -> #N/A | F28: ='Customs Invoice'!F28 -> 0 | G28: ='Customs Invoice'!G28 -> 0 | H28: ='Customs Invoice'!H28 -> #N/A | I28: ='Customs Invoice'!I28 -> 0 | J28: ='Customs Invoice'!J28 -> 0 | K28: =L28/G28 -> #DIV/0! | L28: ='Customs Invoice'!L28 -> 0 | R28: =L28 -> 0 | S28: =I28 -> 0
B29: 9 | C29: =CONCATENATE("FGG-",MID(E29,1,3),MID(E29,10,1),"-ASU") -> #N/A | D29: ='Customs Invoice'!D29 -> #N/A | E29: ='Customs Invoice'!E29 -> #N/A | F29: ='Customs Invoice'!F29 -> 0 | G29: ='Customs Invoice'!G29 -> 0 | H29: ='Customs Invoice'!H29 -> #N/A | I29: ='Customs Invoice'!I29 -> 0 | J29: ='Customs Invoice'!J29 -> 0 | K29: =L29/G29 -> #DIV/0! | L29: ='Customs Invoice'!L29 -> 0 | R29: =L29 -> 0 | S29: =I29 -> 0
B30: 10 | C30: =CONCATENATE("FGG-",MID(E30,1,3),MID(E30,10,1),"-ASU") -> #N/A | D30: ='Customs Invoice'!D30 -> #N/A | E30: ='Customs Invoice'!E30 -> #N/A | F30: ='Customs Invoice'!F30 -> - | G30: ='Customs Invoice'!G30 -> 0 | H30: ='Customs Invoice'!H30 -> #N/A | I30: ='Customs Invoice'!I30 -> 0 | J30: ='Customs Invoice'!J30 -> 0 | K30: =L30/G30 -> #DIV/0! | L30: ='Customs Invoice'!L30 -> 0 | R30: =L30 -> 0 | S30: =I30 -> 0
B31: 11 | C31: =CONCATENATE("FGG-",MID(E31,1,3),MID(E31,10,1),"-ASU") -> #N/A | D31: ='Customs Invoice'!D31 -> #N/A | E31: ='Customs Invoice'!E31 -> #N/A | F31: ='Customs Invoice'!F31 -> - | G31: ='Customs Invoice'!G31 -> 0 | H31: ='Customs Invoice'!H31 -> #N/A | I31: ='Customs Invoice'!I31 -> 0 | J31: ='Customs Invoice'!J31 -> 0 | K31: =L31/G31 -> #DIV/0! | L31: ='Customs Invoice'!L31 -> 0 | R31: =L31 -> 0 | S31: =I31 -> 0
B32: 12 | C32: =CONCATENATE("FGG-",MID(E32,1,3),MID(E32,10,1),"-ASU") -> #N/A | D32: ='Customs Invoice'!D32 -> #N/A | E32: ='Customs Invoice'!E32 -> #N/A | F32: ='Customs Invoice'!F32 -> - | G32: ='Customs Invoice'!G32 -> 0 | H32: ='Customs Invoice'!H32 -> #N/A | I32: ='Customs Invoice'!I32 -> 0 | J32: ='Customs Invoice'!J32 -> 0 | K32: =L32/G32 -> #DIV/0! | L32: ='Customs Invoice'!L32 -> 0 | R32: =L32 -> 0 | S32: =I32 -> 0
... B40: 20 | C40: =CONCATENATE("FGG-",MID(E40,1,3),MID(E40,10,1),"-ASU") -> #N/A | D40: ='Customs Invoice'!D40 -> #N/A | E40: ='Customs Invoice'!E40 -> #N/A | F40: ='Customs Invoice'!F40 -> - | G40: ='Customs Invoice'!G40 -> 0 | H40: ='Customs Invoice'!H40 -> #N/A | I40: ='Customs Invoice'!I40 -> 0 | J40: ='Customs Invoice'!J40 -> 0 | K40: =L40/G40 -> #DIV/0! | L40: ='Customs Invoice'!L40 -> 0 | R40: =L40 -> 0 | S40: =I40 -> 0
E41: TOTAL | G41: =SUM(G21:G40) -> 0 | I41: =SUM(I21:I40) -> 0 | J41: =SUM(J21:J40) -> #DIV/0! | L41: =SUM(L21:L40) -> 0 | M41: =SUM(M21:M40) -> 0 | N41: =SUM(N21:N40) -> 0 | O41: =SUM(O21:O40) -> 0 | P41: =SUM(P21:P40) -> 0
B43: BOX 2 = GOLD JEWELRY
B44: No | C44: ID Code | D44: USA harmonized code | E44: Item | F44: ID | G44: Qty/Pcs,Pair | I44: N.Weight | J44: G.Weight | K44: Unit Value (material & manufacturing cost) | L44: Total Value (material & manufacturing cost) | M44: Manufacturing Cost (nilai maklon) | P44: Manufacturing + Dia + Gold for US
C45: =CONCATENATE("MFGG","-",MID(E45,1,3),MID(E45,10,1),"-","IDD") -> #N/A | D45: =VLOOKUP(F45,Sheet2!$A$2:$D$31,4,0) -> #N/A | E45: =VLOOKUP(F45,Sheet2!$A$2:$D$31,2,0) -> #N/A | H45: =VLOOKUP(F45,Sheet2!$A$2:$D$31,3,0) -> #N/A | K45: =L45/G45 -> #DIV/0!
C46: =CONCATENATE("MFGG","-",MID(E46,1,3),MID(E46,10,1),"-","IDD") -> #N/A | D46: =VLOOKUP(F46,Sheet2!$A$2:$D$31,4,0) -> #N/A | E46: =VLOOKUP(F46,Sheet2!$A$2:$D$31,2,0) -> #N/A | H46: =VLOOKUP(F46,Sheet2!$A$2:$D$31,3,0) -> #N/A | K46: =L46/G46 -> #DIV/0!
C47: =CONCATENATE("MFGG","-",MID(E47,1,3),MID(E47,10,1),"-","IDD") -> #N/A | D47: =VLOOKUP(F47,Sheet2!$A$2:$D$31,4,0) -> #N/A | E47: =VLOOKUP(F47,Sheet2!$A$2:$D$31,2,0) -> #N/A | H47: =VLOOKUP(F47,Sheet2!$A$2:$D$31,3,0) -> #N/A | K47: =L47/G47 -> #DIV/0!
C48: =CONCATENATE("MFGG","-",MID(E48,1,3),MID(E48,10,1),"-","IDD") -> #N/A | D48: =VLOOKUP(F48,Sheet2!$A$2:$D$31,4,0) -> #N/A | E48: =VLOOKUP(F48,Sheet2!$A$2:$D$31,2,0) -> #N/A | H48: =VLOOKUP(F48,Sheet2!$A$2:$D$31,3,0) -> #N/A | K48: =L48/G48 -> #DIV/0!
C49: =CONCATENATE("MFGG","-",MID(E49,1,3),MID(E49,10,1),"-","IDD") -> #N/A | D49: =VLOOKUP(F49,Sheet2!$A$2:$D$31,4,0) -> #N/A | E49: =VLOOKUP(F49,Sheet2!$A$2:$D$31,2,0) -> #N/A | H49: =VLOOKUP(F49,Sheet2!$A$2:$D$31,3,0) -> #N/A | K49: =L49/G49 -> #DIV/0!
...

Sheet Int. Customs Invoice
A1: PT. VERONIQUE INDONESIA
A2: Jl. Raya Purwonegoro Rt. 007/003, Purwonegoro, Banjarnegara, Jawa Tengah, Zip Code : 53472, INDONESIA
A3: CUSTOMS INVOICE
A4: Seller: | B4: PT. VERONIQUE INDONESIA | H4: Invoice No. & Date : | J4: ='Customs Invoice'!K4 -> 0
B5: Jl. Raya Purwonegoro Rt. 007/003 Purwonegoro Banjarnegara | H5: L/C No. & Date) :
B6: Jawa Tengah Zip Code : 53472, INDONESIA | H6: ='Customs Invoice'!I6 -> BILL TO : | J6: ='Customs Invoice'!K6 -> 0
B7: Tel: 62-286-598-8594 Fax: 62-286-598-8650 | J7: ='Customs Invoice'!K7 -> 0
B8: NPWP :0315202689529000 | J8: ='Customs Invoice'!K8 -> 0
A9: Consignee: | B9: ='Customs Invoice'!B9 -> 0 | J9: ='Customs Invoice'!K9 -> 0
B10: ='Customs Invoice'!B10 -> 0 | J10: ='Customs Invoice'!K10 -> 0
B11: ='Customs Invoice'!B11 -> 0 | J11: ='Customs Invoice'!K11 -> 0
B12: ='Customs Invoice'!B12 -> 0
B13: ='Customs Invoice'!B13 -> 0 | H13: Other References: | J13: Country of Origin : INDONESIA
B14: ='Customs Invoice'!B14 -> 0 | J14: B/L No. :
A15: Departure Date: | B15: ='Customs Invoice'!B15 -> 0 | C15: Incoterm: FCA | D15: COUNTRY OF ORIGIN: INDONESIA | J15: A/C No. :
A16: Vessel/Flight: | B16: ='Customs Invoice'!B16 -> 0 | D16: From : INDONESIA | J16: C/T No. : 1
A17: ='Customs Invoice'!A17 -> To : | H17: Terms of Payment: | J17: 30 Day's Net
B18: =CONCATENATE("PT Veronique to International Customers_",LEFT('Customs Invoice'!K4,13)," Customs Invoice_New Merchandise") -> PT Veronique to International Customers_ Customs Invoice_New Merchandise
B19: BOX 1 = GOLD JEWELRY
B20: Origin | C20: Item description | D20: Entry Line | E20: Gross weight | F20: Net weight | G20: Sequence | H20: Manufacturing ID code | I20: Quantity | K20: Total value (gold value + stone value + manufacturing value) | L20: Value of return of customer's stones | M20: Applicable manufacturing value
B21: Indonesia | C21: ='Customs Invoice'!E21 -> #N/A | D21: 1 | E21: ='Customs Invoice'!J21 -> #DIV/0! | F21: ='Customs Invoice'!I21 -> 0 | G21: A | H21: ='Customs Invoice'!C21 -> #N/A | I21: ='Customs Invoice'!G21 -> 0 | J21: ='Customs Invoice'!H21 -> #N/A | K21: ='Customs Invoice'!P21 -> 0 | L21: ='Customs Invoice'!N21 -> 0 | M21: ='Customs Invoice'!M21 -> 0
C22: ='Customs Invoice'!E22 -> #N/A | D22: 2 | E22: ='Customs Invoice'!J22 -> 0 | F22: ='Customs Invoice'!I22 -> 0 | G22: A | H22: ='Customs Invoice'!C22 -> #N/A | I22: ='Customs Invoice'!G22 -> 0 | J22: ='Customs Invoice'!H22 -> #N/A | K22: ='Customs Invoice'!P22 -> 0 | L22: ='Customs Invoice'!N22 -> 0 | M22: ='Customs Invoice'!M22 -> 0
C23: ='Customs Invoice'!E23 -> #N/A | D23: 3 | E23: ='Customs Invoice'!J23 -> 0 | F23: ='Customs Invoice'!I23 -> 0 | G23: A | H23: ='Customs Invoice'!C23 -> #N/A | I23: ='Customs Invoice'!G23 -> 0 | J23: ='Customs Invoice'!H23 -> #N/A | K23: ='Customs Invoice'!P23 -> 0 | L23: ='Customs Invoice'!N23 -> 0 | M23: ='Customs Invoice'!M23 -> 0
C24: ='Customs Invoice'!E24 -> #N/A | D24: 4 | E24: ='Customs Invoice'!J24 -> 0 | F24: ='Customs Invoice'!I24 -> 0 | G24: A | H24: ='Customs Invoice'!C24 -> #N/A | I24: ='Customs Invoice'!G24 -> 0 | J24: ='Customs Invoice'!H24 -> #N/A | K24: ='Customs Invoice'!P24 -> 0 | L24: ='Customs Invoice'!N24 -> 0 | M24: ='Customs Invoice'!M24 -> 0
C25: ='Customs Invoice'!E25 -> #N/A | D25: 5 | E25: ='Customs Invoice'!J25 -> 0 | F25: ='Customs Invoice'!I25 -> 0 | G25: A | H25: ='Customs Invoice'!C25 -> #N/A | I25: ='Customs Invoice'!G25 -> 0 | J25: ='Customs Invoice'!H25 -> #N/A | K25: ='Customs Invoice'!P25 -> 0 | L25: ='Customs Invoice'!N25 -> 0 | M25: ='Customs Invoice'!M25 -> 0
C26: ='Customs Invoice'!E26 -> #N/A | D26: 6 | E26: ='Customs Invoice'!J26 -> 0 | F26: ='Customs Invoice'!I26 -> 0 | G26: A | H26: ='Customs Invoice'!C26 -> #N/A | I26: ='Customs Invoice'!G26 -> 0 | J26: ='Customs Invoice'!H26 -> #N/A | K26: ='Customs Invoice'!P26 -> 0 | L26: ='Customs Invoice'!N26 -> 0 | M26: ='Customs Invoice'!M26 -> 0
C27: ='Customs Invoice'!E27 -> #N/A | D27: 7 | E27: ='Customs Invoice'!J27 -> 0 | F27: ='Customs Invoice'!I27 -> 0 | G27: A | H27: ='Customs Invoice'!C27 -> #N/A | I27: ='Customs Invoice'!G27 -> 0 | J27: ='Customs Invoice'!H27 -> #N/A | K27: ='Customs Invoice'!P27 -> 0 | L27: ='Customs Invoice'!N27 -> 0 | M27: ='Customs Invoice'!M27 -> 0
C28: ='Customs Invoice'!E28 -> #N/A | D28: 8 | E28: ='Customs Invoice'!J28 -> 0 | F28: ='Customs Invoice'!I28 -> 0 | G28: A | H28: ='Customs Invoice'!C28 -> #N/A | I28: ='Customs Invoice'!G28 -> 0 | J28: ='Customs Invoice'!H28 -> #N/A | K28: ='Customs Invoice'!P28 -> 0 | L28: ='Customs Invoice'!N28 -> 0 | M28: ='Customs Invoice'!M28 -> 0
C29: ='Customs Invoice'!E29 -> #N/A | D29: 9 | E29: ='Customs Invoice'!J29 -> 0 | F29: ='Customs Invoice'!I29 -> 0 | G29: A | H29: ='Customs Invoice'!C29 -> #N/A | I29: ='Customs Invoice'!G29 -> 0 | J29: ='Customs Invoice'!H29 -> #N/A | K29: ='Customs Invoice'!P29 -> 0 | L29: ='Customs Invoice'!N29 -> 0 | M29: ='Customs Invoice'!M29 -> 0
C30: ='Customs Invoice'!E30 -> #N/A | D30: 10 | E30: ='Customs Invoice'!J30 -> 0 | F30: ='Customs Invoice'!I30 -> 0 | G30: A | H30: ='Customs Invoice'!C30 -> #N/A | I30: ='Customs Invoice'!G30 -> 0 | J30: ='Customs Invoice'!H30 -> #N/A | K30: ='Customs Invoice'!P30 -> 0 | L30: ='Customs Invoice'!N30 -> 0 | M30: ='Customs Invoice'!M30 -> 0
E31: =SUM(E21:E30) -> #DIV/0! | F31: =SUM(F21:F30) -> 0 | I31: =SUM(I21:I30) -> 0 | K31: =SUM(K21:K30) -> 0 | L31: =SUM(L21:L30) -> 0 | M31: =SUM(M21:M30) -> 0
F33: Manufacturing ID code | G33: Gross weight | H33: Net weight | I33: Total QTY | K33: Total value (gold value + stone value + manufacturing value) | L33: Value of return of customer's stones | M33: Applicable manufacturing value
E34: =C21 -> #N/A | F34: =H21 -> #N/A | G34: =E21 -> #DIV/0! | H34: =F21 -> 0 | I34: =I21 -> 0 | J34: =J21 -> #N/A | K34: =K21 -> 0 | L34: =L21 -> 0 | M34: =M21 -> 0
E35: =C22 -> #N/A | F35: =H22 -> #N/A | G35: =E22 -> 0 | H35: =F22 -> 0 | I35: =I22 -> 0 | J35: =J22 -> #N/A | K35: =K22 -> 0 | L35: =L22 -> 0 | M35: =M22 -> 0
E36: =C23 -> #N/A | F36: =H23 -> #N/A | G36: =E23 -> 0 | H36: =F23 -> 0 | I36: =I23 -> 0 | J36: =J23 -> #N/A | K36: =K23 -> 0 | L36: =L23 -> 0 | M36: =M23 -> 0
E37: =C24 -> #N/A | F37: =H24 -> #N/A | G37: =E24 -> 0 | H37: =F24 -> 0 | I37: =I24 -> 0 | J37: =J24 -> #N/A | K37: =K24 -> 0 | L37: =L24 -> 0 | M37: =M24 -> 0
E38: =C25 -> #N/A | F38: =H25 -> #N/A | G38: =E25 -> 0 | H38: =F25 -> 0 | I38: =I25 -> 0 | J38: =J25 -> #N/A | K38: =K25 -> 0 | L38: =L25 -> 0 | M38: =M25 -> 0
E39: =C26 -> #N/A | F39: =H26 -> #N/A | G39: =E26 -> 0 | H39: =F26 -> 0 | I39: =I26 -> 0 | J39: =J26 -> #N/A | K39: =K26 -> 0 | L39: =L26 -> 0 | M39: =M26 -> 0
E40: =C27 -> #N/A | F40: =H27 -> #N/A | G40: =E27 -> 0 | H40: =F27 -> 0 | I40: =I27 -> 0 | J40: =J27 -> #N/A | K40: =K27 -> 0 | L40: =L27 -> 0 | M40: =M27 -> 0
E41: =C28 -> #N/A | F41: =H28 -> #N/A | G41: =E28 -> 0 | H41: =F28 -> 0 | I41: =I28 -> 0 | J41: =J28 -> #N/A | K41: =K28 -> 0 | L41: =L28 -> 0 | M41: =M28 -> 0
...

Sheet Sheet2
A1: ID | B1: NAMA | C1: UNIT | D1: HS CODE
A2: 14KB | B2: 14K Gold Bracelet | C2: Pcs | D2: 7113.19.5091 | F2: Pcs
A3: 14KB1 | B3: 14K Gold Bracelet | C3: Pcs | D3: 9903.03.01 | F3: Pcs
A4: 14KE | B4: 14K Gold Earring | C4: Pairs | D4: 7113.19.5091 | F4: Pairs
A5: 14KE1 | B5: 14K Gold Earring | C5: Pairs | D5: 9903.03.01 | F5: Pairs
A6: 14KN | B6: 14K Gold Necklace | C6: Pcs | D6: 7113.19.2900 | F6: Pcs
A7: 14KN1 | B7: 14K Gold Necklace | C7: Pcs | D7: 9903.03.01 | F7: Pcs
A8: 14KP | B8: 14K Gold Pendant | C8: Pcs | D8: 7113.19.5091 | F8: Pcs
A9: 14KP1 | B9: 14K Gold Pendant | C9: Pcs | D9: 9903.03.01 | F9: Pcs
A10: 14KR | B10: 14K Gold Ring | C10: Pcs | D10: 7113.19.5091 | F10: Pcs
A11: 14KR1 | B11: 14K Gold Ring | C11: Pcs | D11: 9903.03.01 | F11: Pcs
A12: 18KB | B12: 18K Gold Bracelet | C12: Pcs | D12: 7113.19.5091 | F12: Pcs
A13: 18KB1 | B13: 18K Gold Bracelet | C13: Pcs | D13: 9903.03.01 | F13: Pcs
... A21: 18KR1 | B21: 18K Gold Ring | C21: Pcs | D21: 9903.03.01 | F21: Pcs

Sheet Sheet3
A1: ID | B1: NAMA | C1: UNIT | D1: HS CODE
A2: 10KB | B2: 10K Gold Bracelet | C2: Pcs | D2: 7113.19.5091
A3: 10KE | B3: 10K Gold Earring | C3: Pairs | D3: 7113.19.5091
A4: 10KN | B4: 10K Gold Necklace | C4: Pcs | D4: 7113.19.2900
A5: 10KN KING | B5: 10K Gold Necklace | C5: Pcs | D5: 7113.19.2100
A6: 10KP | B6: 10K Gold Pendant | C6: Pcs | D6: 7113.19.5091
A7: 10KR | B7: 10K Gold Ring | C7: Pcs | D7: 7113.19.5091
A8: 14KB | B8: 14K Gold Bracelet | C8: Pcs | D8: 7113.19.5091
A9: 14KE | B9: 14K Gold Earring | C9: Pairs | D9: 7113.19.5091
A10: 14KN | B10: 14K Gold Necklace | C10: Pcs | D10: 7113.19.2900
A11: 14KP | B11: 14K Gold Pendant | C11: Pcs | D11: 7113.19.5091
A12: 14KR | B12: 14K Gold Ring | C12: Pcs | D12: 7113.19.5091
... A31: 18KN KING | B31: 18K Gold Necklace | C31: Pcs | D31: 7113.19.2100
